title : 에러 처리



**47.1 에러 처리의 필요성**
**47.2 try...catch...finally 문**
**47.3 Error 객체**
**47.4 throw 문**
**47.5 에러의 전파**





## 47.1 에러 처리의 필요성(47-01)

```javascript
console.log('[Start]');

foo(); // ReferenceError: foo is not defined
// 발생한 에러를 방치하면 프로그램은 강제 종료된다.

// 에러에 의해 프로그램이 강제 종료되어 아래 코드는 실행되지 않는다.
console.log('[End]');
```

### 47-02

```javascript
console.log('[Start]');

try {
  foo();
} catch (error) {
  console.error('[에러 발생]', error);
  // [에러 발생] ReferenceError: foo is not defined
}

// 발생한 에러에 적절한 대응을 하면 프로그램이 강제 종료되지 않는다.
console.log('[End]');
```

### 47-03

* 예외적인 상황에 적절하게 대응하지 않으면 에러로 이어질 가능성 높음

```javascript
// DOM에 button 요소가 존재하지 않으면 querySelector 메서드는 에러를 발생시키지 않고 null을 반환한다.
const $button = document.querySelector('button'); // null

$button.classList.add('disabled');
// TypeError: Cannot read property 'classList' of null
```

### 47-04

* 이 예제는 에러를 발생 시킨다

```javascript
const $elem = document.querySelector('#1');
// DOMException: Failed to execute 'querySelector' on 'Document': '#1' is not a valid selector.
```

### 47-05

* 그러나 이 예제는 null을 반환해서 조건문으로 처리하지 않으면 다음 처리에서 에러로 이어질 가능성 높음

```javascript
// DOM에 button 요소가 존재하는 경우 querySelector 메서드는 에러를 발생시키지 않고 null을 반환한다.
const $button = document.querySelector('button'); // null
$button?.classList.add('disabled');
```

## 47.2 try...catch...finally 문(47-06)

```javascript
console.log('[Start]');

try {
  // 실행할 코드(에러가 발생할 가능성이 있는 코드)
  foo();
} catch (err) {
  // try 코드 블록에서 에러가 발생하면 이 코드 블록의 코드가 실행된다.
  // err에는 try 코드 블록에서 발생한 Error 객체가 전달된다.
  console.error(err); // ReferenceError: foo is not defined
} finally {
  // 에러 발생과 상관없이 반드시 한 번 실행된다.
  console.log('finally');
}

// try...catch...finally 문으로 에러를 처리하면 프로그램이 강제 종료되지 않는다.
console.log('[End]');
```

## 47.3 Error 객체(47-07)

* 에러를 상세히 설명하는 에러 메시지를 인수로 받을 수 있다

```javascript
const error = new Error('invalid');
```

### 47-08

```javascript
1 @ 1;    // SyntaxError: Invalid or unexpected token
foo();    // ReferenceError: foo is not defined
null.foo; // TypeError: Cannot read property 'foo' of null
new Array(-1); // RangeError: Invalid array length
decodeURIComponent('%'); // URIError: URI malformed
```

## 47.4 throw 문(47-09)

* Error 생성자 함수로 에러 객체를 생성하는거지 발생하는건 아니다

```javascript
try {
  // 에러 객체를 생성한다고 에러가 발생하는 것은 아니다.
  new Error('something wrong');
} catch (error) {
  console.log(error);
}
```

### 47-10

* 에러를 발생시키려면 try 코드 블록에서 throw 문으로 에러 객체를 던져야 한다

```javascript
try {
  // 에러 객체를 던지면 catch 코드 블록이 실행되기 시작한다.
  throw new Error('something wrong');
} catch (error) {
  console.log(error);
}
```

### 47-11

```javascript
// 외부에서 전달받은 콜백 함수를 n번만큼 반복 호출한다
const repeat = (n, f) => {
  // 매개변수 f에 전달된 인수가 함수가 아니면 TypeError를 발생시킨다.
  if (typeof f !== 'function') throw new TypeError('f must be a function');

  for (var i = 0; i < n; i++) {
    f(i); // i를 전달하면서 f를 호출
  }
};

try {
  repeat(2, 1); // 두 번째 인수가 함수가 아니므로 TypeError가 발생(throw)한다.
} catch (err) {
  console.error(err); // TypeError: f must be a function
}
```

## 47.5 에러의 전파(47-12)

* 에러는 호출자 방향으로 전파. 즉, foo 호출이 젤마지막이였으니 젤 늦게 실행 컨텍스트 push했을텐데 이때 에러가 발생해서 호출자 방향인 전역 실행 컨텍스트로 전파되고, 이때 bar, baz도 지나친다

* 따라서 throw된 에러를 중간에 캐치하여 적절히 대응하면 코드의 실행 흐름을 복구할 수도 있다

```javascript
const foo = () => {
  throw Error('foo에서 발생한 에러'); // ④
};

const bar = () => {
  foo(); // ③
};

const baz = () => {
  bar(); // ②
};

try {
  baz(); // ①
} catch (err) {
  console.error(err);
}
```
